Workbook

Sheet Raw_Returns
A1: date | B1: Information Technology | C1: Health Care | D1: Financials | E1: Consumer Discretionary | F1: Industrials | G1: Communication Services | H1: Consumer Staples | I1: Energy | J1: Materials | K1: Utilities | L1: Real Estate
A2: 45839 | B2: 0.036888096 | C2: 0.012800627 | D2: 0.034832695 | E2: 0.040314645 | F2: 0.01967851 | G2: 0.027152045 | H2: 0.0019446959 | I2: 0.031004115 | J2: 0.033019574 | K2: 0.03114835 | L2: -0.00034464968
A3: 45870 | B3: -0.035425763 | C3: 0.0043174656 | D3: -0.036477032 | E3: -0.03229749 | F3: -0.0011202802 | G3: 0.033762301 | H3: -0.0084300127 | I3: 0.0074435906 | J3: 0.00098050964 | K3: -0.016829564 | L3: 0.01132392
A4: 45901 | B4: 0.0044953161 | C4: 0.0058015387 | D4: 0.010734575 | E4: 0.047170729 | F4: 0.013476219 | G4: -0.018487361 | H4: 0.040347944 | I4: 0.030619057 | J4: -0.0044678828 | K4: 0.046705034 | L4: 0.0070421715
A5: 45931 | B5: 0.068013623 | C5: 0.066096975 | D5: 0.079750538 | E5: 0.075003787 | F5: 0.048443121 | G5: 0.085359244 | H5: 0.051373798 | I5: 0.057337332 | J5: 0.068390917 | K5: 0.0098696356 | L5: 0.082689584
A6: 45962 | B6: -0.021827678 | C6: -0.013173989 | D6: 0.013266583 | E6: -0.015177802 | F6: 0.014816075 | G6: 0.00037480638 | H6: -0.011483192 | I6: -0.029536936 | J6: -0.00016153079 | K6: 0.010985768 | L6: -0.016689667
A7: 45992 | B7: 0.0047146466 | C7: -0.0069945315 | D7: 0.0019253395 | E7: 0.010594952 | F7: 0.025691048 | G7: -0.0073456253 | H7: 0.0093777878 | I7: -0.0096418369 | J7: 0.047899364 | K7: 0.043058099 | L7: -0.007465339
A8: 46023 | B8: 0.063683308 | C8: 0.048459103 | D8: 0.075972398 | E8: 0.10602221 | F8: 0.073286736 | G8: 0.073003728 | H8: 0.048201084 | I8: 0.057197371 | J8: 0.067321293 | K8: 0.019331955 | L8: 0.069646729
A9: 46054 | B9: 0.016255924 | C9: 0.069938344 | D9: 0.036545054 | E9: 0.065062469 | F9: 0.060702917 | G9: -0.0010539891 | H9: 0.044526203 | I9: 0.018782105 | J9: 0.044728336 | K9: 0.0099576094 | L9: 0.0044057555
A10: 46082 | B10: 0.016917154 | C10: -0.0094320736 | D10: -0.041427313 | E10: -0.029719121 | F10: -0.0040852037 | G10: -0.015172413 | H10: -0.021047396 | I10: -0.012926792 | J10: -0.011473211 | K10: -0.0039354092 | L10: -0.0035350329
A11: 46113 | B11: 0.029642236 | C11: 0.0040928229 | D11: 0.018275758 | E11: 0.029458635 | F11: 0.018285127 | G11: 0.036844653 | H11: 0.012753318 | I11: 0.034813179 | J11: 0.006328841 | K11: 0.0062668079 | L11: 0.048419656
A12: 46143 | B12: -0.01076665 | C12: 0.0074946967 | D12: -0.020803154 | E12: -0.0060187806 | F12: -0.003835631 | G12: 0.019021173 | H12: -0.014691023 | I12: 0.028240681 | J12: 0.012319749 | K12: -0.036808458 | L12: -0.040052195
A13: 46174 | B13: -0.040718532 | C13: -0.033451685 | D13: 0.0094503354 | E13: 0.0067558744 | F13: 0.019600082 | G13: -0.020994595 | H13: -0.036179273 | I13: -0.0060747149 | J13: 0.0044094705 | K13: -0.0044747951 | L13: -0.0042792154

Sheet Raw_Weights
A1: date | B1: sector | C1: fund_weight | D1: benchmark_weight
A2: 45839 | B2: Information Technology | C2: 0.28138964 | D2: 0.23485485
A3: 45839 | B3: Health Care | C3: 0.14056117 | D3: 0.1180889
A4: 45839 | B4: Financials | C4: 0.13044785 | D4: 0.1566462
A5: 45839 | B5: Consumer Discretionary | C5: 0.12062959 | D5: 0.10560291
A6: 45839 | B6: Industrials | C6: 0.10035587 | D6: 0.1059482
A7: 45839 | B7: Communication Services | C7: 0.082576449 | D7: 0.075997909
A8: 45839 | B8: Consumer Staples | C8: 0.041281274 | D8: 0.07387448
A9: 45839 | B9: Energy | C9: 0.031861433 | D9: 0.038804799
A10: 45839 | B10: Materials | C10: 0.037234774 | D10: 0.034911853
A11: 45839 | B11: Utilities | C11: 0.017478582 | D11: 0.030604732
A12: 45839 | B12: Real Estate | C12: 0.016183371 | D12: 0.024665168
A13: 45870 | B13: Information Technology | C13: 0.28069201 | D13: 0.23978212
... A133: 46174 | B133: Real Estate | C133: 0.014328986 | D133: 0.015013328

Sheet Raw_AUM
A1: date | B1: aum_start_mm | C1: net_flows_mm | D1: market_return_pct | E1: aum_end_mm
A2: 45839 | B2: 2450 | C2: 52.4 | D2: 2.93 | E2: 2574.3
A3: 45870 | B3: 2574.3 | C3: 35.1 | D3: -2.57 | E3: 2543.1
A4: 45901 | B4: 2543.1 | C4: -16.5 | D4: 5.45 | E4: 2665.3
A5: 45931 | B5: 2665.3 | C5: 69.7 | D5: 1.15 | E5: 2765.6
A6: 45962 | B6: 2765.6 | C6: 49.3 | D6: 0.05 | E6: 2816.3
A7: 45992 | B7: 2816.3 | C7: -39 | D7: 3.71 | E7: 2881.9
A8: 46023 | B8: 2881.9 | C8: 53.4 | D8: -2.09 | E8: 2875
A9: 46054 | B9: 2875 | C9: -39.5 | D9: 2.86 | E9: 2917.7
A10: 46082 | B10: 2917.7 | C10: 51.3 | D10: -2.75 | E10: 2888.7
A11: 46113 | B11: 2888.7 | C11: 34.4 | D11: -5.32 | E11: 2769.5
A12: 46143 | B12: 2769.5 | C12: 64.9 | D12: 5.69 | E12: 2991.8
A13: 46174 | B13: 2991.8 | C13: 76.5 | D13: -3.34 | E13: 2968.3

Sheet Summary
B2: BlackRock Systematic Global Equity Fund
B3: Performance Report | Jul 2025 - Jun 2026
B4: Benchmark: MSCI World Index
B6: KEY PERFORMANCE METRICS
B7: Cumulative Fund Return | C7: {=PRODUCT(1+C36:C47)-1} -> 0.2023278
B8: Cumulative Benchmark Return | C8: {=PRODUCT(1+D36:D47)-1} -> 0.2041711
B9: Cumulative Active Return | C9: =C7-C8 -> -0.0018433045
B10: Annualized Fund Volatility | C10: =STDEV(C36:C47)*SQRT(12) -> 0.1033191
B11: Tracking Error | C11: =STDEV(E36:E47)*SQRT(12) -> 0.0038130374
B12: Information Ratio | C12: =(C7-C8)/C11 -> -0.48342156
B13: Sharpe Ratio | C13: =(C7-0.05)/C10 -> 1.4743431
B14: Max Drawdown | C14: =MIN(G36:G47) -> -0.020542145
B15: Best Month | C15: =MAX(C36:C47) -> 0.068464289
B16: Worst Month | C16: =MIN(C36:C47) -> -0.015759925
B18: Month | C18: Fund Return | D18: Benchmark Return | E18: Active Return
B19: Jul 2025 | C19: =C36 -> 0.028639605 | D19: =D36 -> 0.027481447 | E19: =E36 -> 0.0011581574
B20: Aug 2025 | C20: =C37 -> -0.015263357 | D20: =D37 -> -0.014731698 | E20: =E37 -> -0.00053165898
B21: Sep 2025 | C21: =C38 -> 0.012660771 | D21: =D38 -> 0.014031819 | E21: =E38 -> -0.0013710485
B22: Oct 2025 | C22: =C39 -> 0.067553421 | D22: =D39 -> 0.067089626 | E22: =E39 -> 0.00046379498
B23: Nov 2025 | C23: =C40 -> -0.0078827923 | D23: =D40 -> -0.0071877049 | E23: =E40 -> -0.0006950874
B24: Dec 2025 | C24: =C41 -> 0.0060749183 | D24: =D41 -> 0.0071871823 | E24: =E41 -> -0.001112264
B25: Jan 2026 | C25: =C42 -> 0.068464289 | D25: =D42 -> 0.067997407 | E25: =E42 -> 0.00046688164
B26: Feb 2026 | C26: =C43 -> 0.037319835 | D26: =D43 -> 0.037161807 | E26: =E43 -> 0.00015802837
B27: Mar 2026 | C27: =C44 -> -0.0088816788 | D27: =D44 -> -0.010863964 | E27: =E44 -> 0.0019822848
B28: Apr 2026 | C28: =C45 -> 0.022371394 | D28: =D45 -> 0.02198064 | E28: =E45 -> 0.00039075396
B29: May 2026 | C29: =C46 -> -0.0048587937 | D29: =D46 -> -0.0043965608 | E29: =E46 -> -0.00046223296
B30: Jun 2026 | C30: =C47 -> -0.015759925 | D30: =D47 -> -0.013883812 | E30: =E47 -> -0.0018761136
B34: ← Helper calculations (formula source for Summary metrics)
B35: Month | C35: Fund Return | D35: Bench Return | E35: Active Return | F35: Cum Fund (for DD)
B36: 45839 | C36: {=SUMPRODUCT(OFFSET(Raw_Weights!$C$2,0,0,11,1),TRANSPOSE(OFFSET(Raw_Returns!$B$2,0,0,1,11)))} -> 0.028639605 | D36: {=SUMPRODUCT(OFFSET(Raw_Weights!$D$2,0,0,11,1),TRANSPOSE(OFFSET(Raw_Returns!$B$2,0,0,1,11)))} -> 0.027481447 | E36: =C36-D36 -> 0.0011581574 | F36: =1+C36 -> 1.0286396 | G36: =F36/MAX($F$36:F36)-1 -> 0 | H36: =1+D36 -> 1.0274814 | N36: Month | O36: Fund Return | P36: Benchmark Return
B37: 45870 | C37: {=SUMPRODUCT(OFFSET(Raw_Weights!$C$2,11,0,11,1),TRANSPOSE(OFFSET(Raw_Returns!$B$2,1,0,1,11)))} -> -0.015263357 | D37: {=SUMPRODUCT(OFFSET(Raw_Weights!$D$2,11,0,11,1),TRANSPOSE(OFFSET(Raw_Returns!$B$2,1,0,1,11)))} -> -0.014731698 | E37: =C37-D37 -> -0.00053165898 | F37: =F36*(1+C37) -> 1.0129391 | G37: =F37/MAX($F$36:F37)-1 -> -0.015263357 | H37: =H36*(1+D37) -> 1.0123449 | N37: Jul 2025 | O37: =F36-1 -> 0.028639605 | P37: =H36-1 -> 0.027481447
B38: 45901 | C38: {=SUMPRODUCT(OFFSET(Raw_Weights!$C$2,22,0,11,1),TRANSPOSE(OFFSET(Raw_Returns!$B$2,2,0,1,11)))} -> 0.012660771 | D38: {=SUMPRODUCT(OFFSET(Raw_Weights!$D$2,22,0,11,1),TRANSPOSE(OFFSET(Raw_Returns!$B$2,2,0,1,11)))} -> 0.014031819 | E38: =C38-D38 -> -0.0013710485 | F38: =F37*(1+C38) -> 1.0257637 | G38: =F38/MAX($F$36:F38)-1 -> -0.0027958323 | H38: =H37*(1+D38) -> 1.0265499 | N38: Aug 2025 | O38: =F37-1 -> 0.012939111 | P38: =H37-1 -> 0.012344901
B39: 45931 | C39: {=SUMPRODUCT(OFFSET(Raw_Weights!$C$2,33,0,11,1),TRANSPOSE(OFFSET(Raw_Returns!$B$2,3,0,1,11)))} -> 0.067553421 | D39: {=SUMPRODUCT(OFFSET(Raw_Weights!$D$2,33,0,11,1),TRANSPOSE(OFFSET(Raw_Returns!$B$2,3,0,1,11)))} -> 0.067089626 | E39: =C39-D39 -> 0.00046379498 | F39: =F38*(1+C39) -> 1.0950575 | G39: =F39/MAX($F$36:F39)-1 -> 0 | H39: =H38*(1+D39) -> 1.0954208 | N39: Sep 2025 | O39: =F38-1 -> 0.025763701 | P39: =H38-1 -> 0.026549941
B40: 45962 | C40: {=SUMPRODUCT(OFFSET(Raw_Weights!$C$2,44,0,11,1),TRANSPOSE(OFFSET(Raw_Returns!$B$2,4,0,1,11)))} -> -0.0078827923 | D40: {=SUMPRODUCT(OFFSET(Raw_Weights!$D$2,44,0,11,1),TRANSPOSE(OFFSET(Raw_Returns!$B$2,4,0,1,11)))} -> -0.0071877049 | E40: =C40-D40 -> -0.0006950874 | F40: =F39*(1+C40) -> 1.0864254 | G40: =F40/MAX($F$36:F40)-1 -> -0.0078827923 | H40: =H39*(1+D40) -> 1.0875472 | N40: Oct 2025 | O40: =F39-1 -> 0.095057548 | P40: =H39-1 -> 0.095420793
B41: 45992 | C41: {=SUMPRODUCT(OFFSET(Raw_Weights!$C$2,55,0,11,1),TRANSPOSE(OFFSET(Raw_Returns!$B$2,5,0,1,11)))} -> 0.0060749183 | D41: {=SUMPRODUCT(OFFSET(Raw_Weights!$D$2,55,0,11,1),TRANSPOSE(OFFSET(Raw_Returns!$B$2,5,0,1,11)))} -> 0.0071871823 | E41: =C41-D41 -> -0.001112264 | F41: =F40*(1+C41) -> 1.0930254 | G41: =F41/MAX($F$36:F41)-1 -> -0.0018557613 | H41: =H40*(1+D41) -> 1.0953636 | N41: Nov 2025 | O41: =F40-1 -> 0.086425437 | P41: =H40-1 -> 0.087547232
B42: 46023 | C42: {=SUMPRODUCT(OFFSET(Raw_Weights!$C$2,66,0,11,1),TRANSPOSE(OFFSET(Raw_Returns!$B$2,6,0,1,11)))} -> 0.068464289 | D42: {=SUMPRODUCT(OFFSET(Raw_Weights!$D$2,66,0,11,1),TRANSPOSE(OFFSET(Raw_Returns!$B$2,6,0,1,11)))} -> 0.067997407 | E42: =C42-D42 -> 0.00046688164 | F42: =F41*(1+C42) -> 1.1678586 | G42: =F42/MAX($F$36:F42)-1 -> 0 | H42: =H41*(1+D42) -> 1.1698455 | N42: Dec 2025 | O42: =F41-1 -> 0.093025383 | P42: =H41-1 -> 0.095363632
B43: 46054 | C43: {=SUMPRODUCT(OFFSET(Raw_Weights!$C$2,77,0,11,1),TRANSPOSE(OFFSET(Raw_Returns!$B$2,7,0,1,11)))} -> 0.037319835 | D43: {=SUMPRODUCT(OFFSET(Raw_Weights!$D$2,77,0,11,1),TRANSPOSE(OFFSET(Raw_Returns!$B$2,7,0,1,11)))} -> 0.037161807 | E43: =C43-D43 -> 0.00015802837 | F43: =F42*(1+C43) -> 1.2114429 | G43: =F43/MAX($F$36:F43)-1 -> 0 | H43: =H42*(1+D43) -> 1.2133191 | N43: Jan 2026 | O43: =F42-1 -> 0.16785859 | P43: =H42-1 -> 0.16984552
B44: 46082 | C44: {=SUMPRODUCT(OFFSET(Raw_Weights!$C$2,88,0,11,1),TRANSPOSE(OFFSET(Raw_Returns!$B$2,8,0,1,11)))} -> -0.0088816788 | D44: {=SUMPRODUCT(OFFSET(Raw_Weights!$D$2,88,0,11,1),TRANSPOSE(OFFSET(Raw_Returns!$B$2,8,0,1,11)))} -> -0.010863964 | E44: =C44-D44 -> 0.0019822848 | F44: =F43*(1+C44) -> 1.2006832 | G44: =F44/MAX($F$36:F44)-1 -> -0.0088816788 | H44: =H43*(1+D44) -> 1.2001376 | N44: Feb 2026 | O44: =F43-1 -> 0.21144288 | P44: =H43-1 -> 0.21331909
B45: 46113 | C45: {=SUMPRODUCT(OFFSET(Raw_Weights!$C$2,99,0,11,1),TRANSPOSE(OFFSET(Raw_Returns!$B$2,9,0,1,11)))} -> 0.022371394 | D45: {=SUMPRODUCT(OFFSET(Raw_Weights!$D$2,99,0,11,1),TRANSPOSE(OFFSET(Raw_Returns!$B$2,9,0,1,11)))} -> 0.02198064 | E45: =C45-D45 -> 0.00039075396 | F45: =F44*(1+C45) -> 1.2275442 | G45: =F45/MAX($F$36:F45)-1 -> 0 | H45: =H44*(1+D45) -> 1.2265174 | N45: Mar 2026 | O45: =F44-1 -> 0.20068323 | P45: =H44-1 -> 0.20013764
B46: 46143 | C46: {=SUMPRODUCT(OFFSET(Raw_Weights!$C$2,110,0,11,1),TRANSPOSE(OFFSET(Raw_Returns!$B$2,10,0,1,11)))} -> -0.0048587937 | D46: {=SUMPRODUCT(OFFSET(Raw_Weights!$D$2,110,0,11,1),TRANSPOSE(OFFSET(Raw_Returns!$B$2,10,0,1,11)))} -> -0.0043965608 | E46: =C46-D46 -> -0.00046223296 | F46: =F45*(1+C46) -> 1.2215798 | G46: =F46/MAX($F$36:F46)-1 -> -0.0048587937 | H46: =H45*(1+D46) -> 1.221125 | N46: Apr 2026 | O46: =F45-1 -> 0.22754419 | P46: =H45-1 -> 0.22651743
...

Sheet Sector Attribution
J1: HELPER — Sector Alphas & BHB Monthly Calcs | T1: Sector | U1: Total Effect
B2: Sector Attribution Analysis | J2: Sector | K2: Alpha | T2: =B6 -> Consumer Staples | U2: =I6 -> 0.0027677511
B3: Brinson-Hood-Beebower Decomposition (Full Period Aggregate) | J3: Information Technology | K3: 0.001 | T3: =B7 -> Financials | U3: =I7 -> 0.0020676332
J4: Health Care | K4: 0.0005 | T4: =B8 -> Consumer Discretionary | U4: =I8 -> 0.002031635
B5: Sector | C5: Avg Fund Wt | D5: Avg BM Wt | E5: Active Wt | F5: Allocation Effect | G5: Selection Effect | H5: Interaction Effect | I5: Total Effect | J5: Financials | K5: 0.001 | T5: =B9 -> Information Technology | U5: =I9 -> 0.00091458471
B6: Consumer Staples | C6: =AVERAGEIFS(Raw_Weights!$C:$C,Raw_Weights!$B:$B,"Consumer Staples") -> 0.040037893 | D6: =AVERAGEIFS(Raw_Weights!$D:$D,Raw_Weights!$B:$B,"Consumer Staples") -> 0.066416905 | E6: =C6-D6 -> -0.026379012 | F6: =O24+O38+O52+O66+O80+O94+O108+O122+O136+O150+O164+O178 -> 0.0022872963 | G6: =P24+P38+P52+P66+P80+P94+P108+P122+P136+P150+P164+P178 -> 0.00079700285 | H6: =Q24+Q38+Q52+Q66+Q80+Q94+Q108+Q122+Q136+Q150+Q164+Q178 -> -0.00031654814 | I6: =F6+G6+H6 -> 0.0027677511 | J6: Consumer Discretionary | K6: 0.0003 | T6: =B10 -> Communication Services | U6: =I10 -> 0.00070947571
B7: Financials | C7: =AVERAGEIFS(Raw_Weights!$C:$C,Raw_Weights!$B:$B,"Financials") -> 0.12931256 | D7: =AVERAGEIFS(Raw_Weights!$D:$D,Raw_Weights!$B:$B,"Financials") -> 0.15259931 | E7: =C7-D7 -> -0.023286744 | F7: =O20+O34+O48+O62+O76+O90+O104+O118+O132+O146+O160+O174 -> 0.00051588242 | G7: =P20+P34+P48+P62+P76+P90+P104+P118+P132+P146+P160+P174 -> 0.0018311917 | H7: =Q20+Q34+Q48+Q62+Q76+Q90+Q104+Q118+Q132+Q146+Q160+Q174 -> -0.00027944093 | I7: =F7+G7+H7 -> 0.0020676332 | J7: Industrials | K7: -0.0002 | T7: =B11 -> Health Care | U7: =I11 -> 0.00050655078
B8: Consumer Discretionary | C8: =AVERAGEIFS(Raw_Weights!$C:$C,Raw_Weights!$B:$B,"Consumer Discretionary") -> 0.12058504 | D8: =AVERAGEIFS(Raw_Weights!$D:$D,Raw_Weights!$B:$B,"Consumer Discretionary") -> 0.10406777 | E8: =C8-D8 -> 0.016517272 | F8: =O21+O35+O49+O63+O77+O91+O105+O119+O133+O147+O161+O175 -> 0.0015975289 | G8: =P21+P35+P49+P63+P77+P91+P105+P119+P133+P147+P161+P175 -> 0.00037464395 | H8: =Q21+Q35+Q49+Q63+Q77+Q91+Q105+Q119+Q133+Q147+Q161+Q175 -> 5.9462178e-05 | I8: =F8+G8+H8 -> 0.002031635 | J8: Communication Services | K8: 0.0008 | T8: =B12 -> Real Estate | U8: =I12 -> 0.0002317719
B9: Information Technology | C9: =AVERAGEIFS(Raw_Weights!$C:$C,Raw_Weights!$B:$B,"Information Technology") -> 0.28008005 | D9: =AVERAGEIFS(Raw_Weights!$D:$D,Raw_Weights!$B:$B,"Information Technology") -> 0.23489494 | E9: =C9-D9 -> 0.04518511 | F9: =O18+O32+O46+O60+O74+O88+O102+O116+O130+O144+O158+O172 -> -0.0024463758 | G9: =P18+P32+P46+P60+P74+P88+P102+P116+P130+P144+P158+P172 -> 0.0028187392 | H9: =Q18+Q32+Q46+Q60+Q74+Q88+Q102+Q116+Q130+Q144+Q158+Q172 -> 0.00054222132 | I9: =F9+G9+H9 -> 0.00091458471 | J9: Consumer Staples | K9: 0.001 | T9: =B13 -> Utilities | U9: =I13 -> -0.00010233548
B10: Communication Services | C10: =AVERAGEIFS(Raw_Weights!$C:$C,Raw_Weights!$B:$B,"Communication Services") -> 0.084120662 | D10: =AVERAGEIFS(Raw_Weights!$D:$D,Raw_Weights!$B:$B,"Communication Services") -> 0.076620813 | E10: =C10-D10 -> 0.0074998492 | F10: =O23+O37+O51+O65+O79+O93+O107+O121+O135+O149+O163+O177 -> -9.8082641e-05 | G10: =P23+P37+P51+P65+P79+P93+P107+P121+P135+P149+P163+P177 -> 0.0007355598 | H10: =Q23+Q37+Q51+Q65+Q79+Q93+Q107+Q121+Q135+Q149+Q163+Q177 -> 7.1998553e-05 | I10: =F10+G10+H10 -> 0.00070947571 | J10: Energy | K10: 0.0005 | T10: =B14 -> Energy | U10: =I14 -> -0.00067197677
B11: Health Care | C11: =AVERAGEIFS(Raw_Weights!$C:$C,Raw_Weights!$B:$B,"Health Care") -> 0.1447374 | D11: =AVERAGEIFS(Raw_Weights!$D:$D,Raw_Weights!$B:$B,"Health Care") -> 0.12524308 | E11: =C11-D11 -> 0.019494326 | F11: =O19+O33+O47+O61+O75+O89+O103+O117+O131+O145+O159+O173 -> -0.00036187363 | G11: =P19+P33+P47+P61+P75+P89+P103+P117+P131+P145+P159+P173 -> 0.00075145845 | H11: =Q19+Q33+Q47+Q61+Q75+Q89+Q103+Q117+Q131+Q145+Q159+Q173 -> 0.00011696595 | I11: =F11+G11+H11 -> 0.00050655078 | J11: Materials | K11: -0.0003 | T11: =B15 -> Materials | U11: =I15 -> -0.00092029522
B12: Real Estate | C12: =AVERAGEIFS(Raw_Weights!$C:$C,Raw_Weights!$B:$B,"Real Estate") -> 0.016645917 | D12: =AVERAGEIFS(Raw_Weights!$D:$D,Raw_Weights!$B:$B,"Real Estate") -> 0.020256556 | E12: =C12-D12 -> -0.0036106394 | F12: =O28+O42+O56+O70+O84+O98+O112+O126+O140+O154+O168+O182 -> 0.0002117968 | G12: =P28+P42+P56+P70+P84+P98+P112+P126+P140+P154+P168+P182 -> 2.4307868e-05 | H12: =Q28+Q42+Q56+Q70+Q84+Q98+Q112+Q126+Q140+Q154+Q168+Q182 -> -4.3327673e-06 | I12: =F12+G12+H12 -> 0.0002317719 | J12: Utilities | K12: 0.0002 | T12: =B16 -> Industrials | U12: =I16 -> -0.0015744273
B13: Utilities | C13: =AVERAGEIFS(Raw_Weights!$C:$C,Raw_Weights!$B:$B,"Utilities") -> 0.020467929 | D13: =AVERAGEIFS(Raw_Weights!$D:$D,Raw_Weights!$B:$B,"Utilities") -> 0.024934591 | E13: =C13-D13 -> -0.0044666613 | F13: =O27+O41+O55+O69+O83+O97+O111+O125+O139+O153+O167+O181 -> -0.00015145851 | G13: =P27+P41+P55+P69+P83+P97+P111+P125+P139+P153+P167+P181 -> 5.9843017e-05 | H13: =Q27+Q41+Q55+Q69+Q83+Q97+Q111+Q125+Q139+Q153+Q167+Q181 -> -1.0719987e-05 | I13: =F13+G13+H13 -> -0.00010233548 | J13: Real Estate | K13: 0.0001
B14: Energy | C14: =AVERAGEIFS(Raw_Weights!$C:$C,Raw_Weights!$B:$B,"Energy") -> 0.029913077 | D14: =AVERAGEIFS(Raw_Weights!$D:$D,Raw_Weights!$B:$B,"Energy") -> 0.04535264 | E14: =C14-D14 -> -0.015439564 | F14: =O25+O39+O53+O67+O81+O95+O109+O123+O137+O151+O165+O179 -> -0.00085145523 | G14: =P25+P39+P53+P67+P81+P95+P109+P123+P137+P151+P165+P179 -> 0.00027211584 | H14: =Q25+Q39+Q53+Q67+Q81+Q95+Q109+Q123+Q137+Q151+Q165+Q179 -> -9.2637383e-05 | I14: =F14+G14+H14 -> -0.00067197677 | J14: ↑ Sector alphas (hardcoded inputs referenced by monthly BHB grids below)
B15: Materials | C15: =AVERAGEIFS(Raw_Weights!$C:$C,Raw_Weights!$B:$B,"Materials") -> 0.034267471 | D15: =AVERAGEIFS(Raw_Weights!$D:$D,Raw_Weights!$B:$B,"Materials") -> 0.039542427 | E15: =C15-D15 -> -0.0052749553 | F15: =O26+O40+O54+O68+O82+O96+O110+O124+O138+O152+O166+O180 -> -0.00079693232 | G15: =P26+P40+P54+P68+P82+P96+P110+P124+P138+P152+P166+P180 -> -0.00014235274 | H15: =Q26+Q40+Q54+Q68+Q82+Q96+Q110+Q124+Q138+Q152+Q166+Q180 -> 1.8989839e-05 | I15: =F15+G15+H15 -> -0.00092029522
B16: Industrials | C16: =AVERAGEIFS(Raw_Weights!$C:$C,Raw_Weights!$B:$B,"Industrials") -> 0.099832004 | D16: =AVERAGEIFS(Raw_Weights!$D:$D,Raw_Weights!$B:$B,"Industrials") -> 0.11007098 | E16: =C16-D16 -> -0.010238981 | F16: =O22+O36+O50+O64+O78+O92+O106+O120+O134+O148+O162+O176 -> -0.0013348305 | G16: =P22+P36+P50+P64+P78+P92+P106+P120+P134+P148+P162+P176 -> -0.00026417036 | H16: =Q22+Q36+Q50+Q64+Q78+Q92+Q106+Q120+Q134+Q148+Q162+Q176 -> 2.4573554e-05 | I16: =F16+G16+H16 -> -0.0015744273 | J16: 45839
B17: TOTAL | F17: =SUM(F6:F16) -> -0.0014285042 | G17: =SUM(G6:G16) -> 0.0072583396 | H17: =SUM(H6:H16) -> 0.00013053219 | I17: =SUM(I6:I16) -> 0.0059603676 | J17: Sector | K17: Fund Wt | L17: BM Wt | M17: Sector Ret | N17: BM Total Ret | O17: Alloc Effect | P17: Sel Effect | Q17: Inter Effect | R17: Total Effect
J18: =J3 -> Information Technology | K18: =OFFSET(Raw_Weights!$C$2,0,0) -> 0.28138964 | L18: =OFFSET(Raw_Weights!$D$2,0,0) -> 0.23485485 | M18: =OFFSET(Raw_Returns!$B$2,0,0) -> 0.036888096 | N18: {=SUMPRODUCT(OFFSET(Raw_Weights!$D$2,0,0,11,1),TRANSPOSE(OFFSET(Raw_Returns!$B$2,0,0,1,11)))} -> 0.027481447 | O18: =(K18-L18)*(M18-N18) -> 0.00043773645 | P18: =L18*$K$3 -> 0.00023485485 | Q18: =(K18-L18)*$K$3 -> 4.653479e-05 | R18: =O18+P18+Q18 -> 0.00071912609
J19: =J4 -> Health Care | K19: =OFFSET(Raw_Weights!$C$2,1,0) -> 0.14056117 | L19: =OFFSET(Raw_Weights!$D$2,1,0) -> 0.1180889 | M19: =OFFSET(Raw_Returns!$B$2,0,1) -> 0.012800627 | N19: {=SUMPRODUCT(OFFSET(Raw_Weights!$D$2,0,0,11,1),TRANSPOSE(OFFSET(Raw_Returns!$B$2,0,0,1,11)))} -> 0.027481447 | O19: =(K19-L19)*(M19-N19) -> -0.00032991142 | P19: =L19*$K$4 -> 5.9044448e-05 | Q19: =(K19-L19)*$K$4 -> 1.1236137e-05 | R19: =O19+P19+Q19 -> -0.00025963083
J20: =J5 -> Financials | K20: =OFFSET(Raw_Weights!$C$2,2,0) -> 0.13044785 | L20: =OFFSET(Raw_Weights!$D$2,2,0) -> 0.1566462 | M20: =OFFSET(Raw_Returns!$B$2,0,2) -> 0.034832695 | N20: {=SUMPRODUCT(OFFSET(Raw_Weights!$D$2,0,0,11,1),TRANSPOSE(OFFSET(Raw_Returns!$B$2,0,0,1,11)))} -> 0.027481447 | O20: =(K20-L20)*(M20-N20) -> -0.00019259055 | P20: =L20*$K$5 -> 0.0001566462 | Q20: =(K20-L20)*$K$5 -> -2.6198349e-05 | R20: =O20+P20+Q20 -> -6.2142702e-05
J21: =J6 -> Consumer Discretionary | K21: =OFFSET(Raw_Weights!$C$2,3,0) -> 0.12062959 | L21: =OFFSET(Raw_Weights!$D$2,3,0) -> 0.10560291 | M21: =OFFSET(Raw_Returns!$B$2,0,3) -> 0.040314645 | N21: {=SUMPRODUCT(OFFSET(Raw_Weights!$D$2,0,0,11,1),TRANSPOSE(OFFSET(Raw_Returns!$B$2,0,0,1,11)))} -> 0.027481447 | O21: =(K21-L21)*(M21-N21) -> 0.00019284029 | P21: =L21*$K$6 -> 3.1680874e-05 | Q21: =(K21-L21)*$K$6 -> 4.5080024e-06 | R21: =O21+P21+Q21 -> 0.00022902917
J22: =J7 -> Industrials | K22: =OFFSET(Raw_Weights!$C$2,4,0) -> 0.10035587 | L22: =OFFSET(Raw_Weights!$D$2,4,0) -> 0.1059482 | M22: =OFFSET(Raw_Returns!$B$2,0,4) -> 0.01967851 | N22: {=SUMPRODUCT(OFFSET(Raw_Weights!$D$2,0,0,11,1),TRANSPOSE(OFFSET(Raw_Returns!$B$2,0,0,1,11)))} -> 0.027481447 | O22: =(K22-L22)*(M22-N22) -> 4.3636611e-05 | P22: =L22*$K$7 -> -2.118964e-05 | Q22: =(K22-L22)*$K$7 -> 1.1184662e-06 | R22: =O22+P22+Q22 -> 2.3565437e-05
J23: =J8 -> Communication Services | K23: =OFFSET(Raw_Weights!$C$2,5,0) -> 0.082576449 | L23: =OFFSET(Raw_Weights!$D$2,5,0) -> 0.075997909 | M23: =OFFSET(Raw_Returns!$B$2,0,5) -> 0.027152045 | N23: {=SUMPRODUCT(OFFSET(Raw_Weights!$D$2,0,0,11,1),TRANSPOSE(OFFSET(Raw_Returns!$B$2,0,0,1,11)))} -> 0.027481447 | O23: =(K23-L23)*(M23-N23) -> -2.1669835e-06 | P23: =L23*$K$8 -> 6.0798327e-05 | Q23: =(K23-L23)*$K$8 -> 5.2628323e-06 | R23: =O23+P23+Q23 -> 6.3894176e-05
J24: =J9 -> Consumer Staples | K24: =OFFSET(Raw_Weights!$C$2,6,0) -> 0.041281274 | L24: =OFFSET(Raw_Weights!$D$2,6,0) -> 0.07387448 | M24: =OFFSET(Raw_Returns!$B$2,0,6) -> 0.0019446959 | N24: {=SUMPRODUCT(OFFSET(Raw_Weights!$D$2,0,0,11,1),TRANSPOSE(OFFSET(Raw_Returns!$B$2,0,0,1,11)))} -> 0.027481447 | O24: =(K24-L24)*(M24-N24) -> 0.00083232459 | P24: =L24*$K$9 -> 7.387448e-05 | Q24: =(K24-L24)*$K$9 -> -3.2593206e-05 | R24: =O24+P24+Q24 -> 0.00087360586
J25: =J10 -> Energy | K25: =OFFSET(Raw_Weights!$C$2,7,0) -> 0.031861433 | L25: =OFFSET(Raw_Weights!$D$2,7,0) -> 0.038804799 | M25: =OFFSET(Raw_Returns!$B$2,0,7) -> 0.031004115 | N25: {=SUMPRODUCT(OFFSET(Raw_Weights!$D$2,0,0,11,1),TRANSPOSE(OFFSET(Raw_Returns!$B$2,0,0,1,11)))} -> 0.027481447 | O25: =(K25-L25)*(M25-N25) -> -2.445917e-05 | P25: =L25*$K$10 -> 1.9402399e-05 | Q25: =(K25-L25)*$K$10 -> -3.4716828e-06 | R25: =O25+P25+Q25 -> -8.5284536e-06
J26: =J11 -> Materials | K26: =OFFSET(Raw_Weights!$C$2,8,0) -> 0.037234774 | L26: =OFFSET(Raw_Weights!$D$2,8,0) -> 0.034911853 | M26: =OFFSET(Raw_Returns!$B$2,0,8) -> 0.033019574 | N26: {=SUMPRODUCT(OFFSET(Raw_Weights!$D$2,0,0,11,1),TRANSPOSE(OFFSET(Raw_Returns!$B$2,0,0,1,11)))} -> 0.027481447 | O26: =(K26-L26)*(M26-N26) -> 1.2864631e-05 | P26: =L26*$K$11 -> -1.0473556e-05 | Q26: =(K26-L26)*$K$11 -> -6.9687632e-07 | R26: =O26+P26+Q26 -> 1.694199e-06
J27: =J12 -> Utilities | K27: =OFFSET(Raw_Weights!$C$2,9,0) -> 0.017478582 | L27: =OFFSET(Raw_Weights!$D$2,9,0) -> 0.030604732 | M27: =OFFSET(Raw_Returns!$B$2,0,9) -> 0.03114835 | N27: {=SUMPRODUCT(OFFSET(Raw_Weights!$D$2,0,0,11,1),TRANSPOSE(OFFSET(Raw_Returns!$B$2,0,0,1,11)))} -> 0.027481447 | O27: =(K27-L27)*(M27-N27) -> -4.8132322e-05 | P27: =L27*$K$12 -> 6.1209464e-06 | Q27: =(K27-L27)*$K$12 -> -2.6252301e-06 | R27: =O27+P27+Q27 -> -4.4636605e-05
J28: =J13 -> Real Estate | K28: =OFFSET(Raw_Weights!$C$2,10,0) -> 0.016183371 | L28: =OFFSET(Raw_Weights!$D$2,10,0) -> 0.024665168 | M28: =OFFSET(Raw_Returns!$B$2,0,10) -> -0.00034464968 | N28: {=SUMPRODUCT(OFFSET(Raw_Weights!$D$2,0,0,11,1),TRANSPOSE(OFFSET(Raw_Returns!$B$2,0,0,1,11)))} -> 0.027481447 | O28: =(K28-L28)*(M28-N28) -> 0.00023601531 | P28: =L28*$K$13 -> 2.4665168e-06 | Q28: =(K28-L28)*$K$13 -> -8.4817974e-07 | R28: =O28+P28+Q28 -> 0.00023763365
J30: 45870
J31: Sector | K31: Fund Wt | L31: BM Wt | M31: Sector Ret | N31: BM Total Ret | O31: Alloc Effect | P31: Sel Effect | Q31: Inter Effect | R31: Total Effect
J32: =J3 -> Information Technology | K32: =OFFSET(Raw_Weights!$C$2,11,0) -> 0.28069201 | L32: =OFFSET(Raw_Weights!$D$2,11,0) -> 0.23978212 | M32: =OFFSET(Raw_Returns!$B$2,1,0) -> -0.035425763 | N32: {=SUMPRODUCT(OFFSET(Raw_Weights!$D$2,11,0,11,1),TRANSPOSE(OFFSET(Raw_Returns!$B$2,1,0,1,11)))} -> -0.014731698 | O32: =(K32-L32)*(M32-N32) -> -0.00084659185 | P32: =L32*$K$3 -> 0.00023978212 | Q32: =(K32-L32)*$K$3 -> 4.0909888e-05 | R32: =O32+P32+Q32 -> -0.00056589984
J33: =J4 -> Health Care | K33: =OFFSET(Raw_Weights!$C$2,12,0) -> 0.14024147 | L33: =OFFSET(Raw_Weights!$D$2,12,0) -> 0.12412082 | M33: =OFFSET(Raw_Returns!$B$2,1,1) -> 0.0043174656 | N33: {=SUMPRODUCT(OFFSET(Raw_Weights!$D$2,11,0,11,1),TRANSPOSE(OFFSET(Raw_Returns!$B$2,1,0,1,11)))} -> -0.014731698 | O33: =(K33-L33)*(M33-N33) -> 0.00030708485 | P33: =L33*$K$4 -> 6.206041e-05 | Q33: =(K33-L33)*$K$4 -> 8.0603237e-06 | R33: =O33+P33+Q33 -> 0.00037720559
J34: =J5 -> Financials | K34: =OFFSET(Raw_Weights!$C$2,13,0) -> 0.12532094 | L34: =OFFSET(Raw_Weights!$D$2,13,0) -> 0.15097543 | M34: =OFFSET(Raw_Returns!$B$2,1,2) -> -0.036477032 | N34: {=SUMPRODUCT(OFFSET(Raw_Weights!$D$2,11,0,11,1),TRANSPOSE(OFFSET(Raw_Returns!$B$2,1,0,1,11)))} -> -0.014731698 | O34: =(K34-L34)*(M34-N34) -> 0.00055786544 | P34: =L34*$K$5 -> 0.00015097543 | Q34: =(K34-L34)*$K$5 -> -2.565449e-05 | R34: =O34+P34+Q34 -> 0.00068318638
J35: =J6 -> Consumer Discretionary | K35: =OFFSET(Raw_Weights!$C$2,14,0) -> 0.11890606 | L35: =OFFSET(Raw_Weights!$D$2,14,0) -> 0.10490842 | M35: =OFFSET(Raw_Returns!$B$2,1,3) -> -0.03229749 | N35: {=SUMPRODUCT(OFFSET(Raw_Weights!$D$2,11,0,11,1),TRANSPOSE(OFFSET(Raw_Returns!$B$2,1,0,1,11)))} -> -0.014731698 | O35: =(K35-L35)*(M35-N35) -> -0.00024587954 | P35: =L35*$K$6 -> 3.1472527e-05 | Q35: =(K35-L35)*$K$6 -> 4.1992906e-06 | R35: =O35+P35+Q35 -> -0.00021020772
J36: =J7 -> Industrials | K36: =OFFSET(Raw_Weights!$C$2,15,0) -> 0.10068856 | L36: =OFFSET(Raw_Weights!$D$2,15,0) -> 0.1116964 | M36: =OFFSET(Raw_Returns!$B$2,1,4) -> -0.0011202802 | N36: {=SUMPRODUCT(OFFSET(Raw_Weights!$D$2,11,0,11,1),TRANSPOSE(OFFSET(Raw_Returns!$B$2,1,0,1,11)))} -> -0.014731698 | O36: =(K36-L36)*(M36-N36) -> -0.00014983241 | P36: =L36*$K$7 -> -2.2339281e-05 | Q36: =(K36-L36)*$K$7 -> 2.2015694e-06 | R36: =O36+P36+Q36 -> -0.00016997012
J37: =J8 -> Communication Services | K37: =OFFSET(Raw_Weights!$C$2,16,0) -> 0.08779717 | L37: =OFFSET(Raw_Weights!$D$2,16,0) -> 0.075275917 | M37: =OFFSET(Raw_Returns!$B$2,1,5) -> 0.033762301 | N37: {=SUMPRODUCT(OFFSET(Raw_Weights!$D$2,11,0,11,1),TRANSPOSE(OFFSET(Raw_Returns!$B$2,1,0,1,11)))} -> -0.014731698 | O37: =(K37-L37)*(M37-N37) -> 0.00060720566 | P37: =L37*$K$8 -> 6.0220734e-05 | Q37: =(K37-L37)*$K$8 -> 1.0017003e-05 | R37: =O37+P37+Q37 -> 0.00067744339
J38: =J9 -> Consumer Staples | K38: =OFFSET(Raw_Weights!$C$2,17,0) -> 0.047317903 | L38: =OFFSET(Raw_Weights!$D$2,17,0) -> 0.063855626 | M38: =OFFSET(Raw_Returns!$B$2,1,6) -> -0.0084300127 | N38: {=SUMPRODUCT(OFFSET(Raw_Weights!$D$2,11,0,11,1),TRANSPOSE(OFFSET(Raw_Returns!$B$2,1,0,1,11)))} -> -0.014731698 | O38: =(K38-L38)*(M38-N38) -> -0.00010421553 | P38: =L38*$K$9 -> 6.3855626e-05 | Q38: =(K38-L38)*$K$9 -> -1.6537723e-05 | R38: =O38+P38+Q38 -> -5.689763e-05
J39: =J10 -> Energy | K39: =OFFSET(Raw_Weights!$C$2,18,0) -> 0.026948644 | L39: =OFFSET(Raw_Weights!$D$2,18,0) -> 0.048263561 | M39: =OFFSET(Raw_Returns!$B$2,1,7) -> 0.0074435906 | N39: {=SUMPRODUCT(OFFSET(Raw_Weights!$D$2,11,0,11,1),TRANSPOSE(OFFSET(Raw_Returns!$B$2,1,0,1,11)))} -> -0.014731698 | O39: =(K39-L39)*(M39-N39) -> -0.00047266444 | P39: =L39*$K$10 -> 2.4131781e-05 | Q39: =(K39-L39)*$K$10 -> -1.0657458e-05 | R39: =O39+P39+Q39 -> -0.00045919012
J40: =J11 -> Materials | K40: =OFFSET(Raw_Weights!$C$2,19,0) -> 0.035809742 | L40: =OFFSET(Raw_Weights!$D$2,19,0) -> 0.03474288 | M40: =OFFSET(Raw_Returns!$B$2,1,8) -> 0.00098050964 | N40: {=SUMPRODUCT(OFFSET(Raw_Weights!$D$2,11,0,11,1),TRANSPOSE(OFFSET(Raw_Returns!$B$2,1,0,1,11)))} -> -0.014731698 | O40: =(K40-L40)*(M40-N40) -> 1.6762758e-05 | P40: =L40*$K$11 -> -1.0422864e-05 | Q40: =(K40-L40)*$K$11 -> -3.2005862e-07 | R40: =O40+P40+Q40 -> 6.0198359e-06
J41: =J12 -> Utilities | K41: =OFFSET(Raw_Weights!$C$2,20,0) -> 0.02175461 | L41: =OFFSET(Raw_Weights!$D$2,20,0) -> 0.023949788 | M41: =OFFSET(Raw_Returns!$B$2,1,9) -> -0.016829564 | N41: {=SUMPRODUCT(OFFSET(Raw_Weights!$D$2,11,0,11,1),TRANSPOSE(OFFSET(Raw_Returns!$B$2,1,0,1,11)))} -> -0.014731698 | O41: =(K41-L41)*(M41-N41) -> 4.6051883e-06 | P41: =L41*$K$12 -> 4.7899577e-06 | Q41: =(K41-L41)*$K$12 -> -4.3903562e-07 | R41: =O41+P41+Q41 -> 8.9561104e-06
...

Sheet Monthly Detail
B2: Monthly Sector Attribution Detail
B3: Total Effect by Sector per Month
B5: Month | C5: Information Technology | D5: Health Care | E5: Financials | F5: Consumer Discretionary | G5: Industrials | H5: Communication Services | I5: Consumer Staples | J5: Energy | K5: Materials | L5: Utilities | M5: Real Estate
B6: Jul 2025 | C6: ='Sector Attribution'!R18 -> 0.00071912609 | D6: ='Sector Attribution'!R19 -> -0.00025963083 | E6: ='Sector Attribution'!R20 -> -6.2142702e-05 | F6: ='Sector Attribution'!R21 -> 0.00022902917 | G6: ='Sector Attribution'!R22 -> 2.3565437e-05 | H6: ='Sector Attribution'!R23 -> 6.3894176e-05 | I6: ='Sector Attribution'!R24 -> 0.00087360586 | J6: ='Sector Attribution'!R25 -> -8.5284536e-06 | K6: ='Sector Attribution'!R26 -> 1.694199e-06 | L6: ='Sector Attribution'!R27 -> -4.4636605e-05 | M6: ='Sector Attribution'!R28 -> 0.00023763365
B7: Aug 2025 | C7: ='Sector Attribution'!R32 -> -0.00056589984 | D7: ='Sector Attribution'!R33 -> 0.00037720559 | E7: ='Sector Attribution'!R34 -> 0.00068318638 | F7: ='Sector Attribution'!R35 -> -0.00021020772 | G7: ='Sector Attribution'!R36 -> -0.00016997012 | H7: ='Sector Attribution'!R37 -> 0.00067744339 | I7: ='Sector Attribution'!R38 -> -5.689763e-05 | J7: ='Sector Attribution'!R39 -> -0.00045919012 | K7: ='Sector Attribution'!R40 -> 6.0198359e-06 | L7: ='Sector Attribution'!R41 -> 8.9561104e-06 | M7: ='Sector Attribution'!R42 -> -0.00020454682
B8: Sep 2025 | C8: ='Sector Attribution'!R46 -> -0.00012592917 | D8: ='Sector Attribution'!R47 -> -0.00011849474 | E8: ='Sector Attribution'!R48 -> 0.00022838333 | F8: ='Sector Attribution'!R49 -> 0.00050122773 | G8: ='Sector Attribution'!R50 -> -1.6487002e-05 | H8: ='Sector Attribution'!R51 -> -0.00011159468 | I8: ='Sector Attribution'!R52 -> -0.00063324846 | J8: ='Sector Attribution'!R53 -> -0.00027656801 | K8: ='Sector Attribution'!R54 -> 1.3987597e-05 | L8: ='Sector Attribution'!R55 -> -0.00020106627 | M8: ='Sector Attribution'!R56 -> -2.3297205e-05
B9: Oct 2025 | C9: ='Sector Attribution'!R60 -> 0.00032699537 | D9: ='Sector Attribution'!R61 -> 5.5675722e-05 | E9: ='Sector Attribution'!R62 -> -0.00012385853 | F9: ='Sector Attribution'!R63 -> 0.00018436678 | G9: ='Sector Attribution'!R64 -> 0.00010459134 | H9: ='Sector Attribution'!R65 -> -5.8097638e-05 | I9: ='Sector Attribution'!R66 -> 0.00055185902 | J9: ='Sector Attribution'!R67 -> 0.00010560592 | K9: ='Sector Attribution'!R68 -> -2.0357988e-05 | L9: ='Sector Attribution'!R69 -> -3.818532e-05 | M9: ='Sector Attribution'!R70 -> -7.8083708e-06
B10: Nov 2025 | C10: ='Sector Attribution'!R74 -> -0.00031627575 | D10: ='Sector Attribution'!R75 -> 1.335652e-05 | E10: ='Sector Attribution'!R76 -> -0.00018591404 | F10: ='Sector Attribution'!R77 -> -0.00012183758 | G10: ='Sector Attribution'!R78 -> -0.00017868492 | H10: ='Sector Attribution'!R79 -> 0.00013990228 | I10: ='Sector Attribution'!R80 -> 0.00012590324 | J10: ='Sector Attribution'!R81 -> 0.00034491358 | K10: ='Sector Attribution'!R82 -> -0.00010146842 | L10: ='Sector Attribution'!R83 -> 7.4680422e-05 | M10: ='Sector Attribution'!R84 -> 0.00012205717
B11: Dec 2025 | C11: ='Sector Attribution'!R88 -> 0.00014983404 | D11: ='Sector Attribution'!R89 -> -0.00010883044 | E11: ='Sector Attribution'!R90 -> 0.00026060064 | F11: ='Sector Attribution'!R91 -> 0.00010659462 | G11: ='Sector Attribution'!R92 -> 5.3314353e-05 | H11: ='Sector Attribution'!R93 -> -5.3677346e-05 | I11: ='Sector Attribution'!R94 -> -4.5736052e-05 | J11: ='Sector Attribution'!R95 -> 0.0002215564 | K11: ='Sector Attribution'!R96 -> -0.0006762781 | L11: ='Sector Attribution'!R97 -> -0.00037970788 | M11: ='Sector Attribution'!R98 -> -1.9385026e-05
B12: Jan 2026 | C12: ='Sector Attribution'!R102 -> 6.2800224e-05 | D12: ='Sector Attribution'!R103 -> -0.0003752563 | E12: ='Sector Attribution'!R104 -> -1.4799708e-05 | F12: ='Sector Attribution'!R105 -> 0.00030923962 | G12: ='Sector Attribution'!R106 -> -0.00013928943 | H12: ='Sector Attribution'!R107 -> 0.00014609045 | I12: ='Sector Attribution'!R108 -> 0.00055994144 | J12: ='Sector Attribution'!R109 -> 0.00016693178 | K12: ='Sector Attribution'!R110 -> -1.2571273e-05 | L12: ='Sector Attribution'!R111 -> 0.00039565914 | M12: ='Sector Attribution'!R112 -> -1.1324713e-05
B13: Feb 2026 | C13: ='Sector Attribution'!R116 -> -0.00072100336 | D13: ='Sector Attribution'!R117 -> 0.00089181515 | E13: ='Sector Attribution'!R118 -> 0.00014560023 | F13: ='Sector Attribution'!R119 -> 0.00052988115 | G13: ='Sector Attribution'!R120 -> -0.00038473003 | H13: ='Sector Attribution'!R121 -> -0.00025167897 | I13: ='Sector Attribution'!R122 -> -9.7645721e-05 | J13: ='Sector Attribution'!R123 -> 0.00030153505 | K13: ='Sector Attribution'!R124 -> -8.9056891e-05 | L13: ='Sector Attribution'!R125 -> 0.00023969975 | M13: ='Sector Attribution'!R126 -> 0.00021445269
B14: Mar 2026 | C14: ='Sector Attribution'!R130 -> 0.0015505596 | D14: ='Sector Attribution'!R131 -> 0.000118536 | E14: ='Sector Attribution'!R132 -> 0.00085720565 | F14: ='Sector Attribution'!R133 -> -0.00017663097 | G14: ='Sector Attribution'!R134 -> -9.8146621e-05 | H14: ='Sector Attribution'!R135 -> 3.4782399e-05 | I14: ='Sector Attribution'!R136 -> 0.00031812569 | J14: ='Sector Attribution'!R137 -> 5.6835475e-05 | K14: ='Sector Attribution'!R138 -> -9.0271627e-06 | L14: ='Sector Attribution'!R139 -> -5.7343264e-05 | M14: ='Sector Attribution'!R140 -> 1.4842643e-07
B15: Apr 2026 | C15: ='Sector Attribution'!R144 -> 0.00060296557 | D15: ='Sector Attribution'!R145 -> -0.00033950263 | E15: ='Sector Attribution'!R146 -> 0.00020788605 | F15: ='Sector Attribution'!R147 -> 0.00017017742 | G15: ='Sector Attribution'!R148 -> 5.6149492e-06 | H15: ='Sector Attribution'!R149 -> 0.00014530469 | I15: ='Sector Attribution'!R150 -> 0.00029543665 | J15: ='Sector Attribution'!R151 -> -0.00018847929 | K15: ='Sector Attribution'!R152 -> 0.00013313478 | L15: ='Sector Attribution'!R153 -> 5.2309173e-05 | M15: ='Sector Attribution'!R154 -> -8.4708266e-05
B16: May 2026 | C16: ='Sector Attribution'!R158 -> -1.7209057e-05 | D16: ='Sector Attribution'!R159 -> 0.0003379709 | E16: ='Sector Attribution'!R160 -> 0.00052182854 | F16: ='Sector Attribution'!R161 -> 5.558132e-06 | G16: ='Sector Attribution'!R162 -> -2.7125001e-05 | H16: ='Sector Attribution'!R163 -> 4.6026686e-05 | I16: ='Sector Attribution'!R164 -> 0.0003208604 | J16: ='Sector Attribution'!R165 -> -0.00087091482 | K16: ='Sector Attribution'!R166 -> -3.8329988e-05 | L16: ='Sector Attribution'!R167 -> -0.00014013675 | M16: ='Sector Attribution'!R168 -> 1.3690283e-05
B17: Jun 2026 | C17: ='Sector Attribution'!R172 -> -0.00075137902 | D17: ='Sector Attribution'!R173 -> -8.6294147e-05 | E17: ='Sector Attribution'!R174 -> -0.00045034266 | F17: ='Sector Attribution'!R175 -> 0.00050423668 | G17: ='Sector Attribution'!R176 -> -0.00074708029 | H17: ='Sector Attribution'!R177 -> -6.8919714e-05 | I17: ='Sector Attribution'!R178 -> 0.00055554662 | J17: ='Sector Attribution'!R179 -> -6.5674281e-05 | K17: ='Sector Attribution'!R180 -> -0.00012804181 | L17: ='Sector Attribution'!R181 -> -1.2563975e-05 | M17: ='Sector Attribution'!R182 -> -5.1399231e-06

Sheet AUM & Flows
A1: w
B2: BlackRock Systematic Global Equity Fund
B3: Assets Under Management & Net Flows ($M)
B5: Month | C5: AUM Start ($M) | D5: Net Flows ($M) | E5: Flow Direction | F5: Cumulative Net Flows ($M) | G5: Market Return | H5: AUM End ($M) | J5: Month | K5: AUM End ($M)
B6: =Raw_AUM!A2 -> 45839 | C6: =Raw_AUM!B2 -> 2450 | D6: =Raw_AUM!C2 -> 52.4 | E6: =IF(Raw_AUM!C2>0,"Inflow","Outflow") -> Inflow | F6: =SUM(D$6:D6) -> 52.4 | G6: =Raw_AUM!D2/100 -> 0.0293 | H6: =Raw_AUM!E2 -> 2574.3 | J6: Jul 2025 | K6: =H6 -> 2574.3
B7: =Raw_AUM!A3 -> 45870 | C7: =Raw_AUM!B3 -> 2574.3 | D7: =Raw_AUM!C3 -> 35.1 | E7: =IF(Raw_AUM!C3>0,"Inflow","Outflow") -> Inflow | F7: =SUM(D$6:D7) -> 87.5 | G7: =Raw_AUM!D3/100 -> -0.0257 | H7: =Raw_AUM!E3 -> 2543.1 | J7: Aug 2025 | K7: =H7 -> 2543.1
B8: =Raw_AUM!A4 -> 45901 | C8: =Raw_AUM!B4 -> 2543.1 | D8: =Raw_AUM!C4 -> -16.5 | E8: =IF(Raw_AUM!C4>0,"Inflow","Outflow") -> Outflow | F8: =SUM(D$6:D8) -> 71 | G8: =Raw_AUM!D4/100 -> 0.0545 | H8: =Raw_AUM!E4 -> 2665.3 | J8: Sep 2025 | K8: =H8 -> 2665.3
B9: =Raw_AUM!A5 -> 45931 | C9: =Raw_AUM!B5 -> 2665.3 | D9: =Raw_AUM!C5 -> 69.7 | E9: =IF(Raw_AUM!C5>0,"Inflow","Outflow") -> Inflow | F9: =SUM(D$6:D9) -> 140.7 | G9: =Raw_AUM!D5/100 -> 0.0115 | H9: =Raw_AUM!E5 -> 2765.6 | J9: Oct 2025 | K9: =H9 -> 2765.6
B10: =Raw_AUM!A6 -> 45962 | C10: =Raw_AUM!B6 -> 2765.6 | D10: =Raw_AUM!C6 -> 49.3 | E10: =IF(Raw_AUM!C6>0,"Inflow","Outflow") -> Inflow | F10: =SUM(D$6:D10) -> 190 | G10: =Raw_AUM!D6/100 -> 0.0005 | H10: =Raw_AUM!E6 -> 2816.3 | J10: Nov 2025 | K10: =H10 -> 2816.3
B11: =Raw_AUM!A7 -> 45992 | C11: =Raw_AUM!B7 -> 2816.3 | D11: =Raw_AUM!C7 -> -39 | E11: =IF(Raw_AUM!C7>0,"Inflow","Outflow") -> Outflow | F11: =SUM(D$6:D11) -> 151 | G11: =Raw_AUM!D7/100 -> 0.0371 | H11: =Raw_AUM!E7 -> 2881.9 | J11: Dec 2025 | K11: =H11 -> 2881.9
B12: =Raw_AUM!A8 -> 46023 | C12: =Raw_AUM!B8 -> 2881.9 | D12: =Raw_AUM!C8 -> 53.4 | E12: =IF(Raw_AUM!C8>0,"Inflow","Outflow") -> Inflow | F12: =SUM(D$6:D12) -> 204.4 | G12: =Raw_AUM!D8/100 -> -0.0209 | H12: =Raw_AUM!E8 -> 2875 | J12: Jan 2026 | K12: =H12 -> 2875
B13: =Raw_AUM!A9 -> 46054 | C13: =Raw_AUM!B9 -> 2875 | D13: =Raw_AUM!C9 -> -39.5 | E13: =IF(Raw_AUM!C9>0,"Inflow","Outflow") -> Outflow | F13: =SUM(D$6:D13) -> 164.9 | G13: =Raw_AUM!D9/100 -> 0.0286 | H13: =Raw_AUM!E9 -> 2917.7 | J13: Feb 2026 | K13: =H13 -> 2917.7
B14: =Raw_AUM!A10 -> 46082 | C14: =Raw_AUM!B10 -> 2917.7 | D14: =Raw_AUM!C10 -> 51.3 | E14: =IF(Raw_AUM!C10>0,"Inflow","Outflow") -> Inflow | F14: =SUM(D$6:D14) -> 216.2 | G14: =Raw_AUM!D10/100 -> -0.0275 | H14: =Raw_AUM!E10 -> 2888.7 | J14: Mar 2026 | K14: =H14 -> 2888.7
B15: =Raw_AUM!A11 -> 46113 | C15: =Raw_AUM!B11 -> 2888.7 | D15: =Raw_AUM!C11 -> 34.4 | E15: =IF(Raw_AUM!C11>0,"Inflow","Outflow") -> Inflow | F15: =SUM(D$6:D15) -> 250.6 | G15: =Raw_AUM!D11/100 -> -0.0532 | H15: =Raw_AUM!E11 -> 2769.5 | J15: Apr 2026 | K15: =H15 -> 2769.5
B16: =Raw_AUM!A12 -> 46143 | C16: =Raw_AUM!B12 -> 2769.5 | D16: =Raw_AUM!C12 -> 64.9 | E16: =IF(Raw_AUM!C12>0,"Inflow","Outflow") -> Inflow | F16: =SUM(D$6:D16) -> 315.5 | G16: =Raw_AUM!D12/100 -> 0.0569 | H16: =Raw_AUM!E12 -> 2991.8 | J16: May 2026 | K16: =H16 -> 2991.8
B17: =Raw_AUM!A13 -> 46174 | C17: =Raw_AUM!B13 -> 2991.8 | D17: =Raw_AUM!C13 -> 76.5 | E17: =IF(Raw_AUM!C13>0,"Inflow","Outflow") -> Inflow | F17: =SUM(D$6:D17) -> 392 | G17: =Raw_AUM!D13/100 -> -0.0334 | H17: =Raw_AUM!E13 -> 2968.3 | J17: Jun 2026 | K17: =H17 -> 2968.3
B18: TOTAL / FINAL | D18: =SUM(D6:D17) -> 392 | F18: =F17 -> 392 | H18: =H17 -> 2968.3
